Traceback (most recent call last):
  File "C:\Users\sotiris\AppData\Local\anaconda3\Lib\site-packages\jupyter_cache\executors\utils.py", line 58, in single_nb_execution
    executenb(
  File "C:\Users\sotiris\AppData\Local\anaconda3\Lib\site-packages\nbclient\client.py", line 1204, in execute
    return NotebookClient(nb=nb, resources=resources, km=km, **kwargs).execute()
           ^^^^^^^^^^^^^^^^^^^^^^^^^^^^^^^^^^^^^^^^^^^^^^^^^^^^^^^^^^^^^^^^^^^^^
  File "C:\Users\sotiris\AppData\Local\anaconda3\Lib\site-packages\nbclient\util.py", line 84, in wrapped
    return just_run(coro(*args, **kwargs))
           ^^^^^^^^^^^^^^^^^^^^^^^^^^^^^^^
  File "C:\Users\sotiris\AppData\Local\anaconda3\Lib\site-packages\nbclient\util.py", line 62, in just_run
    return loop.run_until_complete(coro)
           ^^^^^^^^^^^^^^^^^^^^^^^^^^^^^
  File "C:\Users\sotiris\AppData\Local\anaconda3\Lib\asyncio\base_events.py", line 653, in run_until_complete
    return future.result()
           ^^^^^^^^^^^^^^^
  File "C:\Users\sotiris\AppData\Local\anaconda3\Lib\site-packages\nbclient\client.py", line 663, in async_execute
    await self.async_execute_cell(
  File "C:\Users\sotiris\AppData\Local\anaconda3\Lib\site-packages\nbclient\client.py", line 965, in async_execute_cell
    await self._check_raise_for_error(cell, cell_index, exec_reply)
  File "C:\Users\sotiris\AppData\Local\anaconda3\Lib\site-packages\nbclient\client.py", line 862, in _check_raise_for_error
    raise CellExecutionError.from_cell_and_msg(cell, exec_reply_content)
nbclient.exceptions.CellExecutionError: An error occurred while executing the following cell:
------------------
# Î‘Î½Î¬Î³Î½Ï‰ÏƒÎ· Î´ÎµÎ¹Î³Î¼Î¬Ï„Ï‰Î½ ÏƒÎ®Î¼Î±Ï„Î¿Ï‚ Î±Ï€ÏŒ txt file
with open('files/sima.txt') as f:
    s = [float(x) for x in f]
s=np.array(s)   
print('Î¼Î­Î³ÎµÎ¸Î¿Ï‚ ÏƒÎ®Î¼Î±Ï„Î¿Ï‚=', s.shape)
Fs=8192
------------------

[1;31m---------------------------------------------------------------------------[0m
[1;31mFileNotFoundError[0m                         Traceback (most recent call last)
Cell [1;32mIn[3], line 2[0m
[0;32m      1[0m [38;5;66;03m# Î‘Î½Î¬Î³Î½Ï‰ÏƒÎ· Î´ÎµÎ¹Î³Î¼Î¬Ï„Ï‰Î½ ÏƒÎ®Î¼Î±Ï„Î¿Ï‚ Î±Ï€ÏŒ txt file[39;00m
[1;32m----> 2[0m [38;5;28;01mwith[39;00m [38;5;28mopen[39m([38;5;124m'[39m[38;5;124mfiles/sima.txt[39m[38;5;124m'[39m) [38;5;28;01mas[39;00m f:
[0;32m      3[0m     s [38;5;241m=[39m [[38;5;28mfloat[39m(x) [38;5;28;01mfor[39;00m x [38;5;129;01min[39;00m f]
[0;32m      4[0m s[38;5;241m=[39mnp[38;5;241m.[39marray(s)   

File [1;32m~\AppData\Local\anaconda3\Lib\site-packages\IPython\core\interactiveshell.py:286[0m, in [0;36m_modified_open[1;34m(file, *args, **kwargs)[0m
[0;32m    279[0m [38;5;28;01mif[39;00m file [38;5;129;01min[39;00m {[38;5;241m0[39m, [38;5;241m1[39m, [38;5;241m2[39m}:
[0;32m    280[0m     [38;5;28;01mraise[39;00m [38;5;167;01mValueError[39;00m(
[0;32m    281[0m         [38;5;124mf[39m[38;5;124m"[39m[38;5;124mIPython won[39m[38;5;124m'[39m[38;5;124mt let you open fd=[39m[38;5;132;01m{[39;00mfile[38;5;132;01m}[39;00m[38;5;124m by default [39m[38;5;124m"[39m
[0;32m    282[0m         [38;5;124m"[39m[38;5;124mas it is likely to crash IPython. If you know what you are doing, [39m[38;5;124m"[39m
[0;32m    283[0m         [38;5;124m"[39m[38;5;124myou can use builtins[39m[38;5;124m'[39m[38;5;124m open.[39m[38;5;124m"[39m
[0;32m    284[0m     )
[1;32m--> 286[0m [38;5;28;01mreturn[39;00m io_open(file, [38;5;241m*[39margs, [38;5;241m*[39m[38;5;241m*[39mkwargs)

[1;31mFileNotFoundError[0m: [Errno 2] No such file or directory: 'files/sima.txt'
FileNotFoundError: [Errno 2] No such file or directory: 'files/sima.txt'

